{"uuid": "aa12f5f6-5600-4413-9268-4a61c9b74d76", "children": ["322d90aa-8c7d-4b31-bb02-f8448c4a4b75"], "befores": [{"name": "подключаем удаленный драйвер", "status": "broken", "statusDetails": {"message": "urllib3.exceptions.ProtocolError: ('Connection aborted.', RemoteDisconnected('Remote end closed connection without response'))\n", "trace": "  File \"/usr/local/lib/python3.13/site-packages/pluggy/_callers.py\", line 38, in run_old_style_hookwrapper\n    res = yield\n          ^^^^^\n  File \"/usr/local/lib/python3.13/site-packages/pluggy/_callers.py\", line 139, in _multicall\n    teardown.throw(exception)\n    ~~~~~~~~~~~~~~^^^^^^^^^^^\n  File \"/usr/local/lib/python3.13/site-packages/_pytest/setuponly.py\", line 36, in pytest_fixture_setup\n    return (yield)\n            ^^^^^\n  File \"/usr/local/lib/python3.13/site-packages/pluggy/_callers.py\", line 121, in _multicall\n    res = hook_impl.function(*args)\n  File \"/usr/local/lib/python3.13/site-packages/_pytest/fixtures.py\", line 1195, in pytest_fixture_setup\n    result = call_fixture_func(fixturefunc, request, kwargs)\n  File \"/usr/local/lib/python3.13/site-packages/_pytest/fixtures.py\", line 922, in call_fixture_func\n    fixture_result = next(generator)\n  File \"/app/conftest.py\", line 37, in remote_driver\n    driver = webdriver.Remote(command_executor='http://host.docker.internal:5555/wd/hub', options=options)\n  File \"/usr/local/lib/python3.13/site-packages/selenium/webdriver/remote/webdriver.py\", line 261, in __init__\n    self.start_session(capabilities)\n    ~~~~~~~~~~~~~~~~~~^^^^^^^^^^^^^^\n  File \"/usr/local/lib/python3.13/site-packages/selenium/webdriver/remote/webdriver.py\", line 362, in start_session\n    response = self.execute(Command.NEW_SESSION, caps)[\"value\"]\n               ~~~~~~~~~~~~^^^^^^^^^^^^^^^^^^^^^^^^^^^\n  File \"/usr/local/lib/python3.13/site-packages/selenium/webdriver/remote/webdriver.py\", line 451, in execute\n    response = cast(RemoteConnection, self.command_executor).execute(driver_command, params)\n  File \"/usr/local/lib/python3.13/site-packages/selenium/webdriver/remote/remote_connection.py\", line 404, in execute\n    return self._request(command_info[0], url, body=data)\n           ~~~~~~~~~~~~~^^^^^^^^^^^^^^^^^^^^^^^^^^^^^^^^^\n  File \"/usr/local/lib/python3.13/site-packages/selenium/webdriver/remote/remote_connection.py\", line 428, in _request\n    response = self._conn.request(method, url, body=body, headers=headers, timeout=self._client_config.timeout)\n  File \"/usr/local/lib/python3.13/site-packages/urllib3/_request_methods.py\", line 143, in request\n    return self.request_encode_body(\n           ~~~~~~~~~~~~~~~~~~~~~~~~^\n        method, url, fields=fields, headers=headers, **urlopen_kw\n        ^^^^^^^^^^^^^^^^^^^^^^^^^^^^^^^^^^^^^^^^^^^^^^^^^^^^^^^^^\n    )\n    ^\n  File \"/usr/local/lib/python3.13/site-packages/urllib3/_request_methods.py\", line 278, in request_encode_body\n    return self.urlopen(method, url, **extra_kw)\n           ~~~~~~~~~~~~^^^^^^^^^^^^^^^^^^^^^^^^^\n  File \"/usr/local/lib/python3.13/site-packages/urllib3/poolmanager.py\", line 459, in urlopen\n    response = conn.urlopen(method, u.request_uri, **kw)\n  File \"/usr/local/lib/python3.13/site-packages/urllib3/connectionpool.py\", line 841, in urlopen\n    retries = retries.increment(\n        method, url, error=new_e, _pool=self, _stacktrace=sys.exc_info()[2]\n    )\n  File \"/usr/local/lib/python3.13/site-packages/urllib3/util/retry.py\", line 474, in increment\n    raise reraise(type(error), error, _stacktrace)\n          ~~~~~~~^^^^^^^^^^^^^^^^^^^^^^^^^^^^^^^^^\n  File \"/usr/local/lib/python3.13/site-packages/urllib3/util/util.py\", line 38, in reraise\n    raise value.with_traceback(tb)\n  File \"/usr/local/lib/python3.13/site-packages/urllib3/connectionpool.py\", line 787, in urlopen\n    response = self._make_request(\n        conn,\n    ...<10 lines>...\n        **response_kw,\n    )\n  File \"/usr/local/lib/python3.13/site-packages/urllib3/connectionpool.py\", line 534, in _make_request\n    response = conn.getresponse()\n  File \"/usr/local/lib/python3.13/site-packages/urllib3/connection.py\", line 565, in getresponse\n    httplib_response = super().getresponse()\n  File \"/usr/local/lib/python3.13/http/client.py\", line 1430, in getresponse\n    response.begin()\n    ~~~~~~~~~~~~~~^^\n  File \"/usr/local/lib/python3.13/http/client.py\", line 331, in begin\n    version, status, reason = self._read_status()\n                              ~~~~~~~~~~~~~~~~~^^\n  File \"/usr/local/lib/python3.13/http/client.py\", line 300, in _read_status\n    raise RemoteDisconnected(\"Remote end closed connection without\"\n                             \" response\")\n"}, "start": 1753633319232, "stop": 1753633319236}], "start": 1753633319232, "stop": 1753633319324}